---
layout: post
title: '[C++] 构造函数抛出异常小结'
date: 2020-10-31 02:19:26 +0000 UTC
tag: C++
excerpt: '说明突然想到自己对C构造函数抛出异常的情景非常陌生，在这里总结一下。我自己先百度了一下这个问题，发现已经有的资料的质量实在是不高，或者就是C大神在知乎上写下的类似于：...构造函数的初始化列表里抛异常，前面已经构造好的成员和基类子对象要析构，还没有构造的成员则不能析构。而且这个异常捕获之后必须...'
---
## 说明
突然想到自己对C构造函数抛出异常的情景非常陌生，在这里总结一下。我自己先百度了一下这个问题，发现已经有的资料的质量实在是不高，或者就是C大神在知乎上写下的类似于：


> ...
> 2. 构造函数的初始化列表里抛异常，前面已经构造好的成员和基类子对象要析构，还没有构造的成员则不能析构。而且这个异常捕获之后必须重新抛出（编译器强制），因为C++不允许“半吊子”构造的对象存在。
> 3. 多继承中某个基类的构造函数抛异常，那么已经构造好的基类子对象要析构，还没有构造的基类子对象则不能析构。虚拟继承，虚基类只能析构一次，你慢慢想吧。
> 
...



的回答（[原文](https://www.zhihu.com/question/22889420/answer/22975569)）。我读了几遍都不知道他在说啥。


为了从软件开发人员（而非编译器设计者）的角度出发，先放一段类似于C++面试题的代码在这里：


{%raw%}
```cpp
class Elem {
public:
    Elem() {
        cout << "Elem constructor called" << endl;
    }

    ~Elem() {
        cout << "Elem destructor called" << endl;
    }
};

class Base {
public:
    Base() {
        cout << "Base constructor called" << endl;
    }
    ~Base() {
        cout << "Base destructor called" << endl;
    }
};

class Derived : public Base {
public:
    Derived() : vec_(2, Elem()) {
        cout << "Derived constructor called" << endl;
        throw runtime_error("exception for test");
    }

    ~Derived() {
        cout << "Derived destructor called" << endl;
    }

private:
    vector<Elem> vec_;
};

int main() {
    try {
        Derived();
    } catch (const runtime_error& e) {
        cout << "exception caught: " << e.what() << endl;
    }
}
```
{%endraw%}



问：这段代码输出是啥？


答案：


{%raw%}
```bash
Base constructor called
Elem constructor called
Elem destructor called //注意这里是destruct，这和STL里vector的初始化方法有关
Derived constructor called
Elem destructor called
Elem destructor called
Base destructor called
exception caught: exception for test
```
{%endraw%}



解释：


如果在类`Derived`的构造函数本体中没有异常抛出的话，正常的构造顺序应该为`Base`->`vec_`->`Elem`（两个）-> `Derived`构造函数函数体。但是在有异常的情况下，截至异常抛出点：


1. 所有在抛出点之前构造的类（基类、初始化列表中的类等等）都会被成功构造；
2. 抛出异常的类处于一个pending的状态，并没有被成功构造；
3. 所有在抛出点之后构造的类（子类，尚未被执行到的构造链上的类）都没有被成功构造。



于此同时，C++会进行[stack unwinding](https://en.cppreference.com/w/cpp/language/throw#Stack_unwinding)
)来寻找最近try-block的起点。具体现象是，**在当前try-block里已经被成功构造的类都会被析构，未被成功构造的类都不会被析构**。对，就是这么直接的过程。


关于上面罗列的第二条，也就是pending的类，[这里](https://isocpp.org/wiki/faq/exceptions#selfcleaning-members)有一段更为详细的补充：


> If a constructor throws an exception, the object’s destructor is not run. If your object has already done something that needs to be undone (such as allocating some memory, opening a file, or locking a semaphore), this “stuff that needs to be undone” must be remembered by a data member inside the object.



从上面我们可以知道：


1. 即使构造函数抛出异常，该对象的空间已经被分配（“先分配，再构造”）
2. 我们需要自行负责撤销已经进行的操作：诸如分配空间，打开文件，上锁等



关于前面提到的stack unwinding，补充说明一点：在stack unwinding的过程中，不只是和异常抛出类相关的子类基类，**所有**从异常抛出点到try-block起始点的，已经成功构造的类都会被析构，例如我们在文章开头的“面试题”的基础上，增加一个新类：


{%raw%}
```cpp
class Other {
public:
    Other() {
        cout << "Other constructor called" << endl;
    }

    ~Other() {
        cout << "Other destructor called" << endl;
    }
};
```
{%endraw%}



然后将`main`函数增加一行：


{%raw%}
```cpp
int main() {
    try {
        Other other;
        Derived();
    } catch (const runtime_error& e) {
        cout << "exception caught: " << e.what() << endl;
    }
}
```
{%endraw%}



那么在stack unwinding的过程中也会调用`Other`类的析构函数，运行结果会变成：


{%raw%}
```cpp
Other constructor called
Base constructor called
Elem constructor called
Elem destructor called
Derived constructor called
Elem destructor called
Elem destructor called
Base destructor called
Other destructor called
exception caught: exception for test
```
{%endraw%}



## 解决办法


知道了问题所在，有两种方法常见的方法用来处理构造函数抛出异常的情况。这两种方法并非完全通用，需要根据不同的情况来进行**合理适配**。


1. 使用标记位标记未初始化类



这种方法通过一个标志位判断构造函数是否构造成功，但是需要引入额外的检查和清理造成了类的冗余，**不推荐**。例子：


{%raw%}
```cpp
class Solution1 {
public:
    Solution1() : is_complete_(false) {
        try {
            // initialization
            {
                throw runtime_error("exception for test");
            }
            is_complete_ = true;
        } catch (...) {
            is_complete_ = false;
        }
    }

    bool is_complete() {
        return is_complete_;
    }

private:
    bool is_complete_;
};


int main() {
    Solution1 s;
    if (!s.is_complete()) {
        cout << "start clean up" << endl;
        //...
    }
}
```
{%endraw%}



2. 使用智能指针保护资源



这个方法本质上是为了避免直接使用指针造成的资源泄漏，即使用[RAII](https://en.cppreference.com/w/cpp/language/raii)的思路初始化资源。例子：


{%raw%}
```cpp
class Solution2 {
public:
    Solution2() : data(make_unique<int*>(10)) {
        cout << "Solution2 constructor called" << endl;
        throw runtime_error("exception for test");
    }

private:
    unique_ptr<int> data;
};


int main() {
    try {
        Solution2();
    } catch (const runtime_error& e) {
        cout << "exception caught: " << e.what() << endl;
    }
}
```
{%endraw%}



这里用`unique_ptr`避免了类似于


{%raw%}
```cpp
int* data = new int(10);
```
{%endraw%}



可能造成的内存泄漏，这种方法普适性非常好，**推荐**。


## 结语


以上就是这篇小结的所有内容了，这里涉及了几个C++的小知识点包括：类的构造流程，stack unwinding和RAII。在下篇文章中，我会总结一下析构函数抛出异常的情况及处理办法。
